DEBUG:mysql.connector:# _do_auth(): self._auth_plugin: 
DEBUG:mysql.connector:new_auth_plugin: caching_sha2_password
INFO:werkzeug:[31m[1mWARNING: This is a development server. Do not use it in a production deployment. Use a production WSGI server instead.[0m
 * Running on http://127.0.0.1:5000
INFO:werkzeug:[33mPress CTRL+C to quit[0m
INFO:werkzeug: * Restarting with stat
DEBUG:mysql.connector:# _do_auth(): self._auth_plugin: 
DEBUG:mysql.connector:new_auth_plugin: caching_sha2_password
WARNING:werkzeug: * Debugger is active!
INFO:werkzeug: * Debugger PIN: 128-007-232
DEBUG:mysql.connector:# _do_auth(): self._auth_plugin: 
DEBUG:mysql.connector:new_auth_plugin: caching_sha2_password
INFO:googleapiclient.discovery_cache:file_cache is only supported with oauth2client<4.0.0
DEBUG:mysql.connector:# _do_auth(): self._auth_plugin: 
DEBUG:mysql.connector:new_auth_plugin: caching_sha2_password
ERROR:root:Error: 1064 (42000): You have an error in your SQL syntax; check the manual that corresponds to your MySQL server version for the right syntax to use near '' at line 1
INFO:werkzeug:127.0.0.1 - - [15/Nov/2023 18:02:09] "[35m[1mGET /sample_template/added HTTP/1.1[0m" 500 -
INFO:werkzeug:127.0.0.1 - - [15/Nov/2023 18:02:09] "[36mGET /sample_template/added?__debugger__=yes&cmd=resource&f=style.css HTTP/1.1[0m" 304 -
INFO:werkzeug:127.0.0.1 - - [15/Nov/2023 18:02:09] "[36mGET /sample_template/added?__debugger__=yes&cmd=resource&f=debugger.js HTTP/1.1[0m" 304 -
INFO:werkzeug:127.0.0.1 - - [15/Nov/2023 18:02:09] "[36mGET /sample_template/added?__debugger__=yes&cmd=resource&f=console.png HTTP/1.1[0m" 304 -
INFO:werkzeug:127.0.0.1 - - [15/Nov/2023 18:02:09] "[36mGET /sample_template/added?__debugger__=yes&cmd=resource&f=console.png HTTP/1.1[0m" 304 -
INFO:werkzeug: * Detected change in 'c:\\xampp\\htdocs\\ProjectAutomation\\app.py', reloading
INFO:werkzeug: * Restarting with stat
DEBUG:mysql.connector:# _do_auth(): self._auth_plugin: 
DEBUG:mysql.connector:new_auth_plugin: caching_sha2_password
INFO:werkzeug:[31m[1mWARNING: This is a development server. Do not use it in a production deployment. Use a production WSGI server instead.[0m
 * Running on http://127.0.0.1:5000
INFO:werkzeug:[33mPress CTRL+C to quit[0m
INFO:werkzeug: * Restarting with stat
DEBUG:mysql.connector:# _do_auth(): self._auth_plugin: 
DEBUG:mysql.connector:new_auth_plugin: caching_sha2_password
WARNING:werkzeug: * Debugger is active!
INFO:werkzeug: * Debugger PIN: 128-007-232
DEBUG:mysql.connector:# _do_auth(): self._auth_plugin: 
DEBUG:mysql.connector:new_auth_plugin: caching_sha2_password
DEBUG:google.auth.transport.requests:Making request: POST https://oauth2.googleapis.com/token
DEBUG:urllib3.connectionpool:Starting new HTTPS connection (1): oauth2.googleapis.com:443
DEBUG:urllib3.connectionpool:https://oauth2.googleapis.com:443 "POST /token HTTP/1.1" 200 None
INFO:googleapiclient.discovery_cache:file_cache is only supported with oauth2client<4.0.0
DEBUG:mysql.connector:# _do_auth(): self._auth_plugin: 
DEBUG:mysql.connector:new_auth_plugin: caching_sha2_password
ERROR:root:Error: 1064 (42000): You have an error in your SQL syntax; check the manual that corresponds to your MySQL server version for the right syntax to use near '' at line 1
INFO:werkzeug:127.0.0.1 - - [15/Nov/2023 18:32:39] "[35m[1mGET /sample_template/added HTTP/1.1[0m" 500 -
INFO:werkzeug:127.0.0.1 - - [15/Nov/2023 18:32:39] "[36mGET /sample_template/added?__debugger__=yes&cmd=resource&f=style.css HTTP/1.1[0m" 304 -
INFO:werkzeug:127.0.0.1 - - [15/Nov/2023 18:32:39] "[36mGET /sample_template/added?__debugger__=yes&cmd=resource&f=debugger.js HTTP/1.1[0m" 304 -
INFO:werkzeug:127.0.0.1 - - [15/Nov/2023 18:32:39] "[36mGET /sample_template/added?__debugger__=yes&cmd=resource&f=console.png HTTP/1.1[0m" 304 -
INFO:werkzeug:127.0.0.1 - - [15/Nov/2023 18:32:39] "[36mGET /sample_template/added?__debugger__=yes&cmd=resource&f=console.png HTTP/1.1[0m" 304 -
DEBUG:mysql.connector:# _do_auth(): self._auth_plugin: 
DEBUG:mysql.connector:new_auth_plugin: caching_sha2_password
INFO:googleapiclient.discovery_cache:file_cache is only supported with oauth2client<4.0.0
DEBUG:mysql.connector:# _do_auth(): self._auth_plugin: 
DEBUG:mysql.connector:new_auth_plugin: caching_sha2_password
ERROR:root:Error: 1064 (42000): You have an error in your SQL syntax; check the manual that corresponds to your MySQL server version for the right syntax to use near '' at line 1
INFO:werkzeug:127.0.0.1 - - [15/Nov/2023 18:32:39] "[35m[1mGET /sample_template/added HTTP/1.1[0m" 500 -
INFO:werkzeug:127.0.0.1 - - [15/Nov/2023 18:32:40] "[36mGET /sample_template/added?__debugger__=yes&cmd=resource&f=style.css HTTP/1.1[0m" 304 -
INFO:werkzeug:127.0.0.1 - - [15/Nov/2023 18:32:40] "[36mGET /sample_template/added?__debugger__=yes&cmd=resource&f=debugger.js HTTP/1.1[0m" 304 -
INFO:werkzeug:127.0.0.1 - - [15/Nov/2023 18:32:40] "[36mGET /sample_template/added?__debugger__=yes&cmd=resource&f=console.png HTTP/1.1[0m" 304 -
INFO:werkzeug:127.0.0.1 - - [15/Nov/2023 18:32:40] "[36mGET /sample_template/added?__debugger__=yes&cmd=resource&f=console.png HTTP/1.1[0m" 304 -
INFO:werkzeug: * Detected change in 'c:\\xampp\\htdocs\\ProjectAutomation\\app.py', reloading
INFO:werkzeug: * Restarting with stat
DEBUG:mysql.connector:# _do_auth(): self._auth_plugin: 
DEBUG:mysql.connector:new_auth_plugin: caching_sha2_password
WARNING:werkzeug: * Debugger is active!
INFO:werkzeug: * Debugger PIN: 128-007-232
INFO:werkzeug: * Detected change in 'c:\\xampp\\htdocs\\ProjectAutomation\\app.py', reloading
INFO:werkzeug: * Restarting with stat
DEBUG:mysql.connector:# _do_auth(): self._auth_plugin: 
DEBUG:mysql.connector:new_auth_plugin: caching_sha2_password
WARNING:werkzeug: * Debugger is active!
INFO:werkzeug: * Debugger PIN: 128-007-232
DEBUG:mysql.connector:# _do_auth(): self._auth_plugin: 
DEBUG:mysql.connector:new_auth_plugin: caching_sha2_password
INFO:googleapiclient.discovery_cache:file_cache is only supported with oauth2client<4.0.0
DEBUG:mysql.connector:# _do_auth(): self._auth_plugin: 
DEBUG:mysql.connector:new_auth_plugin: caching_sha2_password
ERROR:root:Error: 1064 (42000): You have an error in your SQL syntax; check the manual that corresponds to your MySQL server version for the right syntax to use near '' at line 1
INFO:werkzeug:127.0.0.1 - - [15/Nov/2023 18:33:24] "[35m[1mGET /sample_template/added HTTP/1.1[0m" 500 -
INFO:werkzeug:127.0.0.1 - - [15/Nov/2023 18:33:25] "[36mGET /sample_template/added?__debugger__=yes&cmd=resource&f=style.css HTTP/1.1[0m" 304 -
INFO:werkzeug:127.0.0.1 - - [15/Nov/2023 18:33:25] "[36mGET /sample_template/added?__debugger__=yes&cmd=resource&f=debugger.js HTTP/1.1[0m" 304 -
INFO:werkzeug:127.0.0.1 - - [15/Nov/2023 18:33:25] "[36mGET /sample_template/added?__debugger__=yes&cmd=resource&f=console.png HTTP/1.1[0m" 304 -
INFO:werkzeug:127.0.0.1 - - [15/Nov/2023 18:33:25] "[36mGET /sample_template/added?__debugger__=yes&cmd=resource&f=console.png HTTP/1.1[0m" 304 -
INFO:werkzeug: * Detected change in 'c:\\xampp\\htdocs\\ProjectAutomation\\app.py', reloading
INFO:werkzeug: * Restarting with stat
DEBUG:mysql.connector:# _do_auth(): self._auth_plugin: 
DEBUG:mysql.connector:new_auth_plugin: caching_sha2_password
WARNING:werkzeug: * Debugger is active!
INFO:werkzeug: * Debugger PIN: 128-007-232
DEBUG:mysql.connector:# _do_auth(): self._auth_plugin: 
DEBUG:mysql.connector:new_auth_plugin: caching_sha2_password
INFO:werkzeug:[31m[1mWARNING: This is a development server. Do not use it in a production deployment. Use a production WSGI server instead.[0m
 * Running on http://127.0.0.1:5000
INFO:werkzeug:[33mPress CTRL+C to quit[0m
INFO:werkzeug: * Restarting with stat
DEBUG:mysql.connector:# _do_auth(): self._auth_plugin: 
DEBUG:mysql.connector:new_auth_plugin: caching_sha2_password
WARNING:werkzeug: * Debugger is active!
INFO:werkzeug: * Debugger PIN: 128-007-232
DEBUG:mysql.connector:# _do_auth(): self._auth_plugin: 
DEBUG:mysql.connector:new_auth_plugin: caching_sha2_password
INFO:werkzeug:127.0.0.1 - - [15/Nov/2023 19:09:50] "[35m[1mGET /hello/added HTTP/1.1[0m" 500 -
ERROR:werkzeug:Error on request:
Traceback (most recent call last):
  File "C:\Users\maxim\AppData\Local\Packages\PythonSoftwareFoundation.Python.3.11_qbz5n2kfra8p0\LocalCache\local-packages\Python311\site-packages\werkzeug\debug\__init__.py", line 330, in debug_application
    app_iter = self.app(environ, start_response)
               ^^^^^^^^^^^^^^^^^^^^^^^^^^^^^^^^^
  File "C:\Users\maxim\AppData\Local\Packages\PythonSoftwareFoundation.Python.3.11_qbz5n2kfra8p0\LocalCache\local-packages\Python311\site-packages\flask\app.py", line 1478, in __call__
    return self.wsgi_app(environ, start_response)
           ^^^^^^^^^^^^^^^^^^^^^^^^^^^^^^^^^^^^^^
  File "C:\Users\maxim\AppData\Local\Packages\PythonSoftwareFoundation.Python.3.11_qbz5n2kfra8p0\LocalCache\local-packages\Python311\site-packages\flask\app.py", line 1458, in wsgi_app
    response = self.handle_exception(e)
               ^^^^^^^^^^^^^^^^^^^^^^^^
  File "C:\Users\maxim\AppData\Local\Packages\PythonSoftwareFoundation.Python.3.11_qbz5n2kfra8p0\LocalCache\local-packages\Python311\site-packages\flask\app.py", line 1455, in wsgi_app
    response = self.full_dispatch_request()
               ^^^^^^^^^^^^^^^^^^^^^^^^^^^^
  File "C:\Users\maxim\AppData\Local\Packages\PythonSoftwareFoundation.Python.3.11_qbz5n2kfra8p0\LocalCache\local-packages\Python311\site-packages\flask\app.py", line 869, in full_dispatch_request
    rv = self.handle_user_exception(e)
         ^^^^^^^^^^^^^^^^^^^^^^^^^^^^^
  File "C:\Users\maxim\AppData\Local\Packages\PythonSoftwareFoundation.Python.3.11_qbz5n2kfra8p0\LocalCache\local-packages\Python311\site-packages\flask\app.py", line 867, in full_dispatch_request
    rv = self.dispatch_request()
         ^^^^^^^^^^^^^^^^^^^^^^^
  File "C:\Users\maxim\AppData\Local\Packages\PythonSoftwareFoundation.Python.3.11_qbz5n2kfra8p0\LocalCache\local-packages\Python311\site-packages\flask\app.py", line 852, in dispatch_request
    return self.ensure_sync(self.view_functions[rule.endpoint])(**view_args)
           ^^^^^^^^^^^^^^^^^^^^^^^^^^^^^^^^^^^^^^^^^^^^^^^^^^^^^^^^^^^^^^^^^
  File "c:\xampp\htdocs\ProjectAutomation\app.py", line 216, in added
    print(rows)
OSError: [Errno 22] Invalid argument

During handling of the above exception, another exception occurred:

Traceback (most recent call last):
  File "C:\Users\maxim\AppData\Local\Packages\PythonSoftwareFoundation.Python.3.11_qbz5n2kfra8p0\LocalCache\local-packages\Python311\site-packages\werkzeug\serving.py", line 362, in run_wsgi
    execute(self.server.app)
  File "C:\Users\maxim\AppData\Local\Packages\PythonSoftwareFoundation.Python.3.11_qbz5n2kfra8p0\LocalCache\local-packages\Python311\site-packages\werkzeug\serving.py", line 325, in execute
    for data in application_iter:
  File "C:\Users\maxim\AppData\Local\Packages\PythonSoftwareFoundation.Python.3.11_qbz5n2kfra8p0\LocalCache\local-packages\Python311\site-packages\werkzeug\debug\__init__.py", line 365, in debug_application
    environ["wsgi.errors"].write("".join(tb.render_traceback_text()))
OSError: [Errno 22] Invalid argument
INFO:werkzeug:127.0.0.1 - - [15/Nov/2023 19:09:50] "[36mGET /hello/added?__debugger__=yes&cmd=resource&f=debugger.js HTTP/1.1[0m" 304 -
INFO:werkzeug:127.0.0.1 - - [15/Nov/2023 19:09:50] "[36mGET /hello/added?__debugger__=yes&cmd=resource&f=style.css HTTP/1.1[0m" 304 -
INFO:werkzeug:127.0.0.1 - - [15/Nov/2023 19:09:50] "[36mGET /hello/added?__debugger__=yes&cmd=resource&f=console.png HTTP/1.1[0m" 304 -
INFO:werkzeug:127.0.0.1 - - [15/Nov/2023 19:09:50] "[36mGET /hello/added?__debugger__=yes&cmd=resource&f=console.png HTTP/1.1[0m" 304 -
DEBUG:mysql.connector:# _do_auth(): self._auth_plugin: 
DEBUG:mysql.connector:new_auth_plugin: caching_sha2_password
INFO:werkzeug:127.0.0.1 - - [15/Nov/2023 19:09:58] "[35m[1mGET / HTTP/1.1[0m" 500 -
ERROR:werkzeug:Error on request:
Traceback (most recent call last):
  File "C:\Users\maxim\AppData\Local\Packages\PythonSoftwareFoundation.Python.3.11_qbz5n2kfra8p0\LocalCache\local-packages\Python311\site-packages\werkzeug\debug\__init__.py", line 330, in debug_application
    app_iter = self.app(environ, start_response)
               ^^^^^^^^^^^^^^^^^^^^^^^^^^^^^^^^^
  File "C:\Users\maxim\AppData\Local\Packages\PythonSoftwareFoundation.Python.3.11_qbz5n2kfra8p0\LocalCache\local-packages\Python311\site-packages\flask\app.py", line 1478, in __call__
    return self.wsgi_app(environ, start_response)
           ^^^^^^^^^^^^^^^^^^^^^^^^^^^^^^^^^^^^^^
  File "C:\Users\maxim\AppData\Local\Packages\PythonSoftwareFoundation.Python.3.11_qbz5n2kfra8p0\LocalCache\local-packages\Python311\site-packages\flask\app.py", line 1458, in wsgi_app
    response = self.handle_exception(e)
               ^^^^^^^^^^^^^^^^^^^^^^^^
  File "C:\Users\maxim\AppData\Local\Packages\PythonSoftwareFoundation.Python.3.11_qbz5n2kfra8p0\LocalCache\local-packages\Python311\site-packages\flask\app.py", line 1455, in wsgi_app
    response = self.full_dispatch_request()
               ^^^^^^^^^^^^^^^^^^^^^^^^^^^^
  File "C:\Users\maxim\AppData\Local\Packages\PythonSoftwareFoundation.Python.3.11_qbz5n2kfra8p0\LocalCache\local-packages\Python311\site-packages\flask\app.py", line 869, in full_dispatch_request
    rv = self.handle_user_exception(e)
         ^^^^^^^^^^^^^^^^^^^^^^^^^^^^^
  File "C:\Users\maxim\AppData\Local\Packages\PythonSoftwareFoundation.Python.3.11_qbz5n2kfra8p0\LocalCache\local-packages\Python311\site-packages\flask\app.py", line 867, in full_dispatch_request
    rv = self.dispatch_request()
         ^^^^^^^^^^^^^^^^^^^^^^^
  File "C:\Users\maxim\AppData\Local\Packages\PythonSoftwareFoundation.Python.3.11_qbz5n2kfra8p0\LocalCache\local-packages\Python311\site-packages\flask\app.py", line 852, in dispatch_request
    return self.ensure_sync(self.view_functions[rule.endpoint])(**view_args)
           ^^^^^^^^^^^^^^^^^^^^^^^^^^^^^^^^^^^^^^^^^^^^^^^^^^^^^^^^^^^^^^^^^
  File "c:\xampp\htdocs\ProjectAutomation\app.py", line 50, in index
    return render_template('index.html', messages=templates)
           ^^^^^^^^^^^^^^^^^^^^^^^^^^^^^^^^^^^^^^^^^^^^^^^^^
  File "C:\Users\maxim\AppData\Local\Packages\PythonSoftwareFoundation.Python.3.11_qbz5n2kfra8p0\LocalCache\local-packages\Python311\site-packages\flask\templating.py", line 152, in render_template
    return _render(app, template, context)
           ^^^^^^^^^^^^^^^^^^^^^^^^^^^^^^^
  File "C:\Users\maxim\AppData\Local\Packages\PythonSoftwareFoundation.Python.3.11_qbz5n2kfra8p0\LocalCache\local-packages\Python311\site-packages\flask\templating.py", line 133, in _render
    rv = template.render(context)
         ^^^^^^^^^^^^^^^^^^^^^^^^
  File "C:\Users\maxim\AppData\Local\Packages\PythonSoftwareFoundation.Python.3.11_qbz5n2kfra8p0\LocalCache\local-packages\Python311\site-packages\jinja2\environment.py", line 1301, in render
    self.environment.handle_exception()
  File "C:\Users\maxim\AppData\Local\Packages\PythonSoftwareFoundation.Python.3.11_qbz5n2kfra8p0\LocalCache\local-packages\Python311\site-packages\jinja2\environment.py", line 936, in handle_exception
    raise rewrite_traceback_stack(source=source)
  File "c:\xampp\htdocs\ProjectAutomation\templates\index.html", line 3, in top-level template code
    {% extends 'base.html' %}
  File "c:\xampp\htdocs\ProjectAutomation\templates\base.html", line 108, in top-level template code
    {% block content %} {% endblock %}
  File "c:\xampp\htdocs\ProjectAutomation\templates\index.html", line 21, in block 'content'
    <a href="{{ url_for('events', template_id=template_id) }}">  <!-- to lead you to the events contained within the template, refer using template_id-->
  File "C:\Users\maxim\AppData\Local\Packages\PythonSoftwareFoundation.Python.3.11_qbz5n2kfra8p0\LocalCache\local-packages\Python311\site-packages\flask\app.py", line 1071, in url_for
    return self.handle_url_build_error(error, endpoint, values)
           ^^^^^^^^^^^^^^^^^^^^^^^^^^^^^^^^^^^^^^^^^^^^^^^^^^^^
  File "C:\Users\maxim\AppData\Local\Packages\PythonSoftwareFoundation.Python.3.11_qbz5n2kfra8p0\LocalCache\local-packages\Python311\site-packages\flask\app.py", line 1060, in url_for
    rv = url_adapter.build(  # type: ignore[union-attr]
         ^^^^^^^^^^^^^^^^^^^^^^^^^^^^^^^^^^^^^^^^^^^^^^
  File "C:\Users\maxim\AppData\Local\Packages\PythonSoftwareFoundation.Python.3.11_qbz5n2kfra8p0\LocalCache\local-packages\Python311\site-packages\werkzeug\routing\map.py", line 919, in build
    raise BuildError(endpoint, values, method, self)
werkzeug.routing.exceptions.BuildError: Could not build url for endpoint 'events' with values ['template_id']. Did you forget to specify values ['template_id10']?

During handling of the above exception, another exception occurred:

Traceback (most recent call last):
  File "C:\Users\maxim\AppData\Local\Packages\PythonSoftwareFoundation.Python.3.11_qbz5n2kfra8p0\LocalCache\local-packages\Python311\site-packages\werkzeug\serving.py", line 362, in run_wsgi
    execute(self.server.app)
  File "C:\Users\maxim\AppData\Local\Packages\PythonSoftwareFoundation.Python.3.11_qbz5n2kfra8p0\LocalCache\local-packages\Python311\site-packages\werkzeug\serving.py", line 325, in execute
    for data in application_iter:
  File "C:\Users\maxim\AppData\Local\Packages\PythonSoftwareFoundation.Python.3.11_qbz5n2kfra8p0\LocalCache\local-packages\Python311\site-packages\werkzeug\debug\__init__.py", line 365, in debug_application
    environ["wsgi.errors"].write("".join(tb.render_traceback_text()))
OSError: [Errno 22] Invalid argument
INFO:werkzeug:127.0.0.1 - - [15/Nov/2023 19:09:58] "[36mGET /?__debugger__=yes&cmd=resource&f=style.css HTTP/1.1[0m" 304 -
INFO:werkzeug:127.0.0.1 - - [15/Nov/2023 19:09:58] "[36mGET /?__debugger__=yes&cmd=resource&f=debugger.js HTTP/1.1[0m" 304 -
INFO:werkzeug:127.0.0.1 - - [15/Nov/2023 19:09:58] "[36mGET /?__debugger__=yes&cmd=resource&f=console.png HTTP/1.1[0m" 304 -
INFO:werkzeug:127.0.0.1 - - [15/Nov/2023 19:09:58] "[36mGET /?__debugger__=yes&cmd=resource&f=console.png HTTP/1.1[0m" 304 -
INFO:werkzeug: * Detected change in 'c:\\xampp\\htdocs\\ProjectAutomation\\app.py', reloading
INFO:werkzeug: * Restarting with stat
INFO:werkzeug: * Detected change in 'c:\\xampp\\htdocs\\ProjectAutomation\\app.py', reloading
INFO:werkzeug: * Restarting with stat
DEBUG:mysql.connector:# _do_auth(): self._auth_plugin: 
DEBUG:mysql.connector:new_auth_plugin: caching_sha2_password
WARNING:werkzeug: * Debugger is active!
INFO:werkzeug: * Debugger PIN: 128-007-232
DEBUG:mysql.connector:# _do_auth(): self._auth_plugin: 
DEBUG:mysql.connector:new_auth_plugin: caching_sha2_password
WARNING:werkzeug: * Debugger is active!
INFO:werkzeug: * Debugger PIN: 128-007-232
INFO:werkzeug: * Detected change in 'c:\\xampp\\htdocs\\ProjectAutomation\\app.py', reloading
INFO:werkzeug: * Restarting with stat
INFO:werkzeug: * Detected change in 'c:\\xampp\\htdocs\\ProjectAutomation\\app.py', reloading
INFO:werkzeug: * Restarting with stat
DEBUG:mysql.connector:# _do_auth(): self._auth_plugin: 
DEBUG:mysql.connector:new_auth_plugin: caching_sha2_password
WARNING:werkzeug: * Debugger is active!
INFO:werkzeug: * Debugger PIN: 128-007-232
DEBUG:mysql.connector:# _do_auth(): self._auth_plugin: 
DEBUG:mysql.connector:new_auth_plugin: caching_sha2_password
WARNING:werkzeug: * Debugger is active!
INFO:werkzeug: * Debugger PIN: 128-007-232
DEBUG:mysql.connector:# _do_auth(): self._auth_plugin: 
DEBUG:mysql.connector:new_auth_plugin: caching_sha2_password
INFO:werkzeug:[31m[1mWARNING: This is a development server. Do not use it in a production deployment. Use a production WSGI server instead.[0m
 * Running on http://127.0.0.1:5000
INFO:werkzeug:[33mPress CTRL+C to quit[0m
INFO:werkzeug: * Restarting with stat
DEBUG:mysql.connector:# _do_auth(): self._auth_plugin: 
DEBUG:mysql.connector:new_auth_plugin: caching_sha2_password
WARNING:werkzeug: * Debugger is active!
INFO:werkzeug: * Debugger PIN: 128-007-232
INFO:werkzeug: * Detected change in 'c:\\xampp\\htdocs\\ProjectAutomation\\main.py', reloading
INFO:werkzeug: * Restarting with stat
DEBUG:mysql.connector:# _do_auth(): self._auth_plugin: 
DEBUG:mysql.connector:new_auth_plugin: caching_sha2_password
WARNING:werkzeug: * Debugger is active!
INFO:werkzeug: * Debugger PIN: 128-007-232
INFO:werkzeug: * Detected change in 'c:\\xampp\\htdocs\\ProjectAutomation\\main.py', reloading
INFO:werkzeug: * Detected change in 'c:\\xampp\\htdocs\\ProjectAutomation\\main.py', reloading
INFO:werkzeug: * Restarting with stat
INFO:werkzeug: * Restarting with stat
DEBUG:mysql.connector:# _do_auth(): self._auth_plugin: 
DEBUG:mysql.connector:new_auth_plugin: caching_sha2_password
WARNING:werkzeug: * Debugger is active!
INFO:werkzeug: * Debugger PIN: 128-007-232
DEBUG:mysql.connector:# _do_auth(): self._auth_plugin: 
DEBUG:mysql.connector:new_auth_plugin: caching_sha2_password
WARNING:werkzeug: * Debugger is active!
INFO:werkzeug: * Debugger PIN: 128-007-232
DEBUG:mysql.connector:# _do_auth(): self._auth_plugin: 
DEBUG:mysql.connector:new_auth_plugin: caching_sha2_password
INFO:werkzeug:127.0.0.1 - - [15/Nov/2023 19:11:10] "[35m[1mGET / HTTP/1.1[0m" 500 -
ERROR:werkzeug:Error on request:
Traceback (most recent call last):
  File "C:\Users\maxim\AppData\Local\Packages\PythonSoftwareFoundation.Python.3.11_qbz5n2kfra8p0\LocalCache\local-packages\Python311\site-packages\werkzeug\debug\__init__.py", line 330, in debug_application
    app_iter = self.app(environ, start_response)
               ^^^^^^^^^^^^^^^^^^^^^^^^^^^^^^^^^
  File "C:\Users\maxim\AppData\Local\Packages\PythonSoftwareFoundation.Python.3.11_qbz5n2kfra8p0\LocalCache\local-packages\Python311\site-packages\flask\app.py", line 1478, in __call__
    return self.wsgi_app(environ, start_response)
           ^^^^^^^^^^^^^^^^^^^^^^^^^^^^^^^^^^^^^^
  File "C:\Users\maxim\AppData\Local\Packages\PythonSoftwareFoundation.Python.3.11_qbz5n2kfra8p0\LocalCache\local-packages\Python311\site-packages\flask\app.py", line 1458, in wsgi_app
    response = self.handle_exception(e)
               ^^^^^^^^^^^^^^^^^^^^^^^^
  File "C:\Users\maxim\AppData\Local\Packages\PythonSoftwareFoundation.Python.3.11_qbz5n2kfra8p0\LocalCache\local-packages\Python311\site-packages\flask\app.py", line 1455, in wsgi_app
    response = self.full_dispatch_request()
               ^^^^^^^^^^^^^^^^^^^^^^^^^^^^
  File "C:\Users\maxim\AppData\Local\Packages\PythonSoftwareFoundation.Python.3.11_qbz5n2kfra8p0\LocalCache\local-packages\Python311\site-packages\flask\app.py", line 869, in full_dispatch_request
    rv = self.handle_user_exception(e)
         ^^^^^^^^^^^^^^^^^^^^^^^^^^^^^
  File "C:\Users\maxim\AppData\Local\Packages\PythonSoftwareFoundation.Python.3.11_qbz5n2kfra8p0\LocalCache\local-packages\Python311\site-packages\flask\app.py", line 867, in full_dispatch_request
    rv = self.dispatch_request()
         ^^^^^^^^^^^^^^^^^^^^^^^
  File "C:\Users\maxim\AppData\Local\Packages\PythonSoftwareFoundation.Python.3.11_qbz5n2kfra8p0\LocalCache\local-packages\Python311\site-packages\flask\app.py", line 852, in dispatch_request
    return self.ensure_sync(self.view_functions[rule.endpoint])(**view_args)
           ^^^^^^^^^^^^^^^^^^^^^^^^^^^^^^^^^^^^^^^^^^^^^^^^^^^^^^^^^^^^^^^^^
  File "c:\xampp\htdocs\ProjectAutomation\app.py", line 50, in index
    return render_template('index.html', messages=templates)
           ^^^^^^^^^^^^^^^^^^^^^^^^^^^^^^^^^^^^^^^^^^^^^^^^^
  File "C:\Users\maxim\AppData\Local\Packages\PythonSoftwareFoundation.Python.3.11_qbz5n2kfra8p0\LocalCache\local-packages\Python311\site-packages\flask\templating.py", line 152, in render_template
    return _render(app, template, context)
           ^^^^^^^^^^^^^^^^^^^^^^^^^^^^^^^
  File "C:\Users\maxim\AppData\Local\Packages\PythonSoftwareFoundation.Python.3.11_qbz5n2kfra8p0\LocalCache\local-packages\Python311\site-packages\flask\templating.py", line 133, in _render
    rv = template.render(context)
         ^^^^^^^^^^^^^^^^^^^^^^^^
  File "C:\Users\maxim\AppData\Local\Packages\PythonSoftwareFoundation.Python.3.11_qbz5n2kfra8p0\LocalCache\local-packages\Python311\site-packages\jinja2\environment.py", line 1301, in render
    self.environment.handle_exception()
  File "C:\Users\maxim\AppData\Local\Packages\PythonSoftwareFoundation.Python.3.11_qbz5n2kfra8p0\LocalCache\local-packages\Python311\site-packages\jinja2\environment.py", line 936, in handle_exception
    raise rewrite_traceback_stack(source=source)
  File "c:\xampp\htdocs\ProjectAutomation\templates\index.html", line 3, in top-level template code
    {% extends 'base.html' %}
  File "c:\xampp\htdocs\ProjectAutomation\templates\base.html", line 108, in top-level template code
    {% block content %} {% endblock %}
  File "c:\xampp\htdocs\ProjectAutomation\templates\index.html", line 21, in block 'content'
    <a href="{{ url_for('events', template_id=template_id) }}">  <!-- to lead you to the events contained within the template, refer using template_id-->
  File "C:\Users\maxim\AppData\Local\Packages\PythonSoftwareFoundation.Python.3.11_qbz5n2kfra8p0\LocalCache\local-packages\Python311\site-packages\flask\app.py", line 1071, in url_for
    return self.handle_url_build_error(error, endpoint, values)
           ^^^^^^^^^^^^^^^^^^^^^^^^^^^^^^^^^^^^^^^^^^^^^^^^^^^^
  File "C:\Users\maxim\AppData\Local\Packages\PythonSoftwareFoundation.Python.3.11_qbz5n2kfra8p0\LocalCache\local-packages\Python311\site-packages\flask\app.py", line 1060, in url_for
    rv = url_adapter.build(  # type: ignore[union-attr]
         ^^^^^^^^^^^^^^^^^^^^^^^^^^^^^^^^^^^^^^^^^^^^^^
  File "C:\Users\maxim\AppData\Local\Packages\PythonSoftwareFoundation.Python.3.11_qbz5n2kfra8p0\LocalCache\local-packages\Python311\site-packages\werkzeug\routing\map.py", line 919, in build
    raise BuildError(endpoint, values, method, self)
werkzeug.routing.exceptions.BuildError: Could not build url for endpoint 'events' with values ['template_id']. Did you forget to specify values ['template_id10']?

During handling of the above exception, another exception occurred:

Traceback (most recent call last):
  File "C:\Users\maxim\AppData\Local\Packages\PythonSoftwareFoundation.Python.3.11_qbz5n2kfra8p0\LocalCache\local-packages\Python311\site-packages\werkzeug\serving.py", line 362, in run_wsgi
    execute(self.server.app)
  File "C:\Users\maxim\AppData\Local\Packages\PythonSoftwareFoundation.Python.3.11_qbz5n2kfra8p0\LocalCache\local-packages\Python311\site-packages\werkzeug\serving.py", line 325, in execute
    for data in application_iter:
  File "C:\Users\maxim\AppData\Local\Packages\PythonSoftwareFoundation.Python.3.11_qbz5n2kfra8p0\LocalCache\local-packages\Python311\site-packages\werkzeug\debug\__init__.py", line 365, in debug_application
    environ["wsgi.errors"].write("".join(tb.render_traceback_text()))
OSError: [Errno 22] Invalid argument
INFO:werkzeug:127.0.0.1 - - [15/Nov/2023 19:11:10] "[36mGET /?__debugger__=yes&cmd=resource&f=style.css HTTP/1.1[0m" 304 -
INFO:werkzeug:127.0.0.1 - - [15/Nov/2023 19:11:10] "[36mGET /?__debugger__=yes&cmd=resource&f=debugger.js HTTP/1.1[0m" 304 -
INFO:werkzeug:127.0.0.1 - - [15/Nov/2023 19:11:10] "[36mGET /?__debugger__=yes&cmd=resource&f=console.png HTTP/1.1[0m" 304 -
INFO:werkzeug:127.0.0.1 - - [15/Nov/2023 19:11:10] "[36mGET /?__debugger__=yes&cmd=resource&f=console.png HTTP/1.1[0m" 304 -
DEBUG:mysql.connector:# _do_auth(): self._auth_plugin: 
DEBUG:mysql.connector:new_auth_plugin: caching_sha2_password
INFO:werkzeug:127.0.0.1 - - [15/Nov/2023 19:11:55] "[35m[1mGET / HTTP/1.1[0m" 500 -
ERROR:werkzeug:Error on request:
Traceback (most recent call last):
  File "C:\Users\maxim\AppData\Local\Packages\PythonSoftwareFoundation.Python.3.11_qbz5n2kfra8p0\LocalCache\local-packages\Python311\site-packages\werkzeug\debug\__init__.py", line 330, in debug_application
    app_iter = self.app(environ, start_response)
               ^^^^^^^^^^^^^^^^^^^^^^^^^^^^^^^^^
  File "C:\Users\maxim\AppData\Local\Packages\PythonSoftwareFoundation.Python.3.11_qbz5n2kfra8p0\LocalCache\local-packages\Python311\site-packages\flask\app.py", line 1478, in __call__
    return self.wsgi_app(environ, start_response)
           ^^^^^^^^^^^^^^^^^^^^^^^^^^^^^^^^^^^^^^
  File "C:\Users\maxim\AppData\Local\Packages\PythonSoftwareFoundation.Python.3.11_qbz5n2kfra8p0\LocalCache\local-packages\Python311\site-packages\flask\app.py", line 1458, in wsgi_app
    response = self.handle_exception(e)
               ^^^^^^^^^^^^^^^^^^^^^^^^
  File "C:\Users\maxim\AppData\Local\Packages\PythonSoftwareFoundation.Python.3.11_qbz5n2kfra8p0\LocalCache\local-packages\Python311\site-packages\flask\app.py", line 1455, in wsgi_app
    response = self.full_dispatch_request()
               ^^^^^^^^^^^^^^^^^^^^^^^^^^^^
  File "C:\Users\maxim\AppData\Local\Packages\PythonSoftwareFoundation.Python.3.11_qbz5n2kfra8p0\LocalCache\local-packages\Python311\site-packages\flask\app.py", line 869, in full_dispatch_request
    rv = self.handle_user_exception(e)
         ^^^^^^^^^^^^^^^^^^^^^^^^^^^^^
  File "C:\Users\maxim\AppData\Local\Packages\PythonSoftwareFoundation.Python.3.11_qbz5n2kfra8p0\LocalCache\local-packages\Python311\site-packages\flask\app.py", line 867, in full_dispatch_request
    rv = self.dispatch_request()
         ^^^^^^^^^^^^^^^^^^^^^^^
  File "C:\Users\maxim\AppData\Local\Packages\PythonSoftwareFoundation.Python.3.11_qbz5n2kfra8p0\LocalCache\local-packages\Python311\site-packages\flask\app.py", line 852, in dispatch_request
    return self.ensure_sync(self.view_functions[rule.endpoint])(**view_args)
           ^^^^^^^^^^^^^^^^^^^^^^^^^^^^^^^^^^^^^^^^^^^^^^^^^^^^^^^^^^^^^^^^^
  File "c:\xampp\htdocs\ProjectAutomation\app.py", line 50, in index
    return render_template('index.html', messages=templates)
           ^^^^^^^^^^^^^^^^^^^^^^^^^^^^^^^^^^^^^^^^^^^^^^^^^
  File "C:\Users\maxim\AppData\Local\Packages\PythonSoftwareFoundation.Python.3.11_qbz5n2kfra8p0\LocalCache\local-packages\Python311\site-packages\flask\templating.py", line 152, in render_template
    return _render(app, template, context)
           ^^^^^^^^^^^^^^^^^^^^^^^^^^^^^^^
  File "C:\Users\maxim\AppData\Local\Packages\PythonSoftwareFoundation.Python.3.11_qbz5n2kfra8p0\LocalCache\local-packages\Python311\site-packages\flask\templating.py", line 133, in _render
    rv = template.render(context)
         ^^^^^^^^^^^^^^^^^^^^^^^^
  File "C:\Users\maxim\AppData\Local\Packages\PythonSoftwareFoundation.Python.3.11_qbz5n2kfra8p0\LocalCache\local-packages\Python311\site-packages\jinja2\environment.py", line 1301, in render
    self.environment.handle_exception()
  File "C:\Users\maxim\AppData\Local\Packages\PythonSoftwareFoundation.Python.3.11_qbz5n2kfra8p0\LocalCache\local-packages\Python311\site-packages\jinja2\environment.py", line 936, in handle_exception
    raise rewrite_traceback_stack(source=source)
  File "c:\xampp\htdocs\ProjectAutomation\templates\index.html", line 3, in top-level template code
    {% extends 'base.html' %}
  File "c:\xampp\htdocs\ProjectAutomation\templates\base.html", line 108, in top-level template code
    {% block content %} {% endblock %}
  File "c:\xampp\htdocs\ProjectAutomation\templates\index.html", line 21, in block 'content'
    <a href="{{ url_for('events', template_id=template_id) }}">  <!-- to lead you to the events contained within the template, refer using template_id-->
  File "C:\Users\maxim\AppData\Local\Packages\PythonSoftwareFoundation.Python.3.11_qbz5n2kfra8p0\LocalCache\local-packages\Python311\site-packages\flask\app.py", line 1071, in url_for
    return self.handle_url_build_error(error, endpoint, values)
           ^^^^^^^^^^^^^^^^^^^^^^^^^^^^^^^^^^^^^^^^^^^^^^^^^^^^
  File "C:\Users\maxim\AppData\Local\Packages\PythonSoftwareFoundation.Python.3.11_qbz5n2kfra8p0\LocalCache\local-packages\Python311\site-packages\flask\app.py", line 1060, in url_for
    rv = url_adapter.build(  # type: ignore[union-attr]
         ^^^^^^^^^^^^^^^^^^^^^^^^^^^^^^^^^^^^^^^^^^^^^^
  File "C:\Users\maxim\AppData\Local\Packages\PythonSoftwareFoundation.Python.3.11_qbz5n2kfra8p0\LocalCache\local-packages\Python311\site-packages\werkzeug\routing\map.py", line 919, in build
    raise BuildError(endpoint, values, method, self)
werkzeug.routing.exceptions.BuildError: Could not build url for endpoint 'events' with values ['template_id']. Did you forget to specify values ['template_id10']?

During handling of the above exception, another exception occurred:

Traceback (most recent call last):
  File "C:\Users\maxim\AppData\Local\Packages\PythonSoftwareFoundation.Python.3.11_qbz5n2kfra8p0\LocalCache\local-packages\Python311\site-packages\werkzeug\serving.py", line 362, in run_wsgi
    execute(self.server.app)
  File "C:\Users\maxim\AppData\Local\Packages\PythonSoftwareFoundation.Python.3.11_qbz5n2kfra8p0\LocalCache\local-packages\Python311\site-packages\werkzeug\serving.py", line 325, in execute
    for data in application_iter:
  File "C:\Users\maxim\AppData\Local\Packages\PythonSoftwareFoundation.Python.3.11_qbz5n2kfra8p0\LocalCache\local-packages\Python311\site-packages\werkzeug\debug\__init__.py", line 365, in debug_application
    environ["wsgi.errors"].write("".join(tb.render_traceback_text()))
OSError: [Errno 22] Invalid argument
INFO:werkzeug:127.0.0.1 - - [15/Nov/2023 19:11:55] "[36mGET /?__debugger__=yes&cmd=resource&f=style.css HTTP/1.1[0m" 304 -
INFO:werkzeug:127.0.0.1 - - [15/Nov/2023 19:11:55] "[36mGET /?__debugger__=yes&cmd=resource&f=debugger.js HTTP/1.1[0m" 304 -
INFO:werkzeug:127.0.0.1 - - [15/Nov/2023 19:11:55] "[36mGET /?__debugger__=yes&cmd=resource&f=console.png HTTP/1.1[0m" 304 -
INFO:werkzeug:127.0.0.1 - - [15/Nov/2023 19:11:55] "[36mGET /?__debugger__=yes&cmd=resource&f=console.png HTTP/1.1[0m" 304 -
INFO:werkzeug: * Detected change in 'c:\\xampp\\htdocs\\ProjectAutomation\\app.py', reloading
INFO:werkzeug: * Detected change in 'c:\\xampp\\htdocs\\ProjectAutomation\\app.py', reloading
INFO:werkzeug: * Restarting with stat
INFO:werkzeug: * Restarting with stat
INFO:werkzeug: * Detected change in 'c:\\xampp\\htdocs\\ProjectAutomation\\app.py', reloading
INFO:werkzeug: * Restarting with stat
DEBUG:mysql.connector:# _do_auth(): self._auth_plugin: 
DEBUG:mysql.connector:new_auth_plugin: caching_sha2_password
WARNING:werkzeug: * Debugger is active!
INFO:werkzeug: * Debugger PIN: 128-007-232
DEBUG:mysql.connector:# _do_auth(): self._auth_plugin: 
DEBUG:mysql.connector:new_auth_plugin: caching_sha2_password
WARNING:werkzeug: * Debugger is active!
INFO:werkzeug: * Debugger PIN: 128-007-232
DEBUG:mysql.connector:# _do_auth(): self._auth_plugin: 
DEBUG:mysql.connector:new_auth_plugin: caching_sha2_password
WARNING:werkzeug: * Debugger is active!
INFO:werkzeug: * Debugger PIN: 128-007-232
INFO:werkzeug: * Detected change in 'c:\\xampp\\htdocs\\ProjectAutomation\\app.py', reloading
INFO:werkzeug: * Detected change in 'c:\\xampp\\htdocs\\ProjectAutomation\\app.py', reloading
INFO:werkzeug: * Restarting with stat
INFO:werkzeug: * Restarting with stat
INFO:werkzeug: * Detected change in 'c:\\xampp\\htdocs\\ProjectAutomation\\app.py', reloading
INFO:werkzeug: * Restarting with stat
DEBUG:mysql.connector:# _do_auth(): self._auth_plugin: 
DEBUG:mysql.connector:new_auth_plugin: caching_sha2_password
WARNING:werkzeug: * Debugger is active!
INFO:werkzeug: * Debugger PIN: 128-007-232
DEBUG:mysql.connector:# _do_auth(): self._auth_plugin: 
DEBUG:mysql.connector:new_auth_plugin: caching_sha2_password
WARNING:werkzeug: * Debugger is active!
INFO:werkzeug: * Debugger PIN: 128-007-232
DEBUG:mysql.connector:# _do_auth(): self._auth_plugin: 
DEBUG:mysql.connector:new_auth_plugin: caching_sha2_password
WARNING:werkzeug: * Debugger is active!
INFO:werkzeug: * Debugger PIN: 128-007-232
DEBUG:mysql.connector:# _do_auth(): self._auth_plugin: 
DEBUG:mysql.connector:new_auth_plugin: caching_sha2_password
INFO:werkzeug:127.0.0.1 - - [15/Nov/2023 19:13:28] "GET / HTTP/1.1" 200 -
DEBUG:mysql.connector:# _do_auth(): self._auth_plugin: 
DEBUG:mysql.connector:new_auth_plugin: caching_sha2_password
INFO:werkzeug:127.0.0.1 - - [15/Nov/2023 19:13:29] "[35m[1mGET /favicon.ico/ HTTP/1.1[0m" 500 -
ERROR:werkzeug:Error on request:
Traceback (most recent call last):
  File "c:\xampp\htdocs\ProjectAutomation\app.py", line 73, in events
    cursor.execute(query2)
  File "C:\Users\maxim\AppData\Local\Packages\PythonSoftwareFoundation.Python.3.11_qbz5n2kfra8p0\LocalCache\local-packages\Python311\site-packages\mysql\connector\cursor.py", line 617, in execute
    self._handle_result(self._connection.cmd_query(stmt))
                        ^^^^^^^^^^^^^^^^^^^^^^^^^^^^^^^^^
  File "C:\Users\maxim\AppData\Local\Packages\PythonSoftwareFoundation.Python.3.11_qbz5n2kfra8p0\LocalCache\local-packages\Python311\site-packages\mysql\connector\opentelemetry\context_propagation.py", line 77, in wrapper
    return method(cnx, *args, **kwargs)
           ^^^^^^^^^^^^^^^^^^^^^^^^^^^^
  File "C:\Users\maxim\AppData\Local\Packages\PythonSoftwareFoundation.Python.3.11_qbz5n2kfra8p0\LocalCache\local-packages\Python311\site-packages\mysql\connector\connection.py", line 1069, in cmd_query
    result = self._handle_result(self._send_cmd(ServerCmd.QUERY, query))
             ^^^^^^^^^^^^^^^^^^^^^^^^^^^^^^^^^^^^^^^^^^^^^^^^^^^^^^^^^^^
  File "C:\Users\maxim\AppData\Local\Packages\PythonSoftwareFoundation.Python.3.11_qbz5n2kfra8p0\LocalCache\local-packages\Python311\site-packages\mysql\connector\connection.py", line 846, in _handle_result
    raise get_exception(packet)
mysql.connector.errors.ProgrammingError: 1049 (42000): Unknown database 'favicon'

During handling of the above exception, another exception occurred:

Traceback (most recent call last):
  File "C:\Users\maxim\AppData\Local\Packages\PythonSoftwareFoundation.Python.3.11_qbz5n2kfra8p0\LocalCache\local-packages\Python311\site-packages\werkzeug\debug\__init__.py", line 330, in debug_application
    app_iter = self.app(environ, start_response)
               ^^^^^^^^^^^^^^^^^^^^^^^^^^^^^^^^^
  File "C:\Users\maxim\AppData\Local\Packages\PythonSoftwareFoundation.Python.3.11_qbz5n2kfra8p0\LocalCache\local-packages\Python311\site-packages\flask\app.py", line 1478, in __call__
    return self.wsgi_app(environ, start_response)
           ^^^^^^^^^^^^^^^^^^^^^^^^^^^^^^^^^^^^^^
  File "C:\Users\maxim\AppData\Local\Packages\PythonSoftwareFoundation.Python.3.11_qbz5n2kfra8p0\LocalCache\local-packages\Python311\site-packages\flask\app.py", line 1458, in wsgi_app
    response = self.handle_exception(e)
               ^^^^^^^^^^^^^^^^^^^^^^^^
  File "C:\Users\maxim\AppData\Local\Packages\PythonSoftwareFoundation.Python.3.11_qbz5n2kfra8p0\LocalCache\local-packages\Python311\site-packages\flask\app.py", line 1455, in wsgi_app
    response = self.full_dispatch_request()
               ^^^^^^^^^^^^^^^^^^^^^^^^^^^^
  File "C:\Users\maxim\AppData\Local\Packages\PythonSoftwareFoundation.Python.3.11_qbz5n2kfra8p0\LocalCache\local-packages\Python311\site-packages\flask\app.py", line 869, in full_dispatch_request
    rv = self.handle_user_exception(e)
         ^^^^^^^^^^^^^^^^^^^^^^^^^^^^^
  File "C:\Users\maxim\AppData\Local\Packages\PythonSoftwareFoundation.Python.3.11_qbz5n2kfra8p0\LocalCache\local-packages\Python311\site-packages\flask\app.py", line 867, in full_dispatch_request
    rv = self.dispatch_request()
         ^^^^^^^^^^^^^^^^^^^^^^^
  File "C:\Users\maxim\AppData\Local\Packages\PythonSoftwareFoundation.Python.3.11_qbz5n2kfra8p0\LocalCache\local-packages\Python311\site-packages\flask\app.py", line 852, in dispatch_request
    return self.ensure_sync(self.view_functions[rule.endpoint])(**view_args)
           ^^^^^^^^^^^^^^^^^^^^^^^^^^^^^^^^^^^^^^^^^^^^^^^^^^^^^^^^^^^^^^^^^
  File "c:\xampp\htdocs\ProjectAutomation\app.py", line 95, in events
    print(f"Error: {err}")
OSError: [Errno 22] Invalid argument

During handling of the above exception, another exception occurred:

Traceback (most recent call last):
  File "C:\Users\maxim\AppData\Local\Packages\PythonSoftwareFoundation.Python.3.11_qbz5n2kfra8p0\LocalCache\local-packages\Python311\site-packages\werkzeug\serving.py", line 362, in run_wsgi
    execute(self.server.app)
  File "C:\Users\maxim\AppData\Local\Packages\PythonSoftwareFoundation.Python.3.11_qbz5n2kfra8p0\LocalCache\local-packages\Python311\site-packages\werkzeug\serving.py", line 325, in execute
    for data in application_iter:
  File "C:\Users\maxim\AppData\Local\Packages\PythonSoftwareFoundation.Python.3.11_qbz5n2kfra8p0\LocalCache\local-packages\Python311\site-packages\werkzeug\debug\__init__.py", line 365, in debug_application
    environ["wsgi.errors"].write("".join(tb.render_traceback_text()))
OSError: [Errno 22] Invalid argument
DEBUG:mysql.connector:# _do_auth(): self._auth_plugin: 
DEBUG:mysql.connector:new_auth_plugin: caching_sha2_password
INFO:werkzeug:127.0.0.1 - - [15/Nov/2023 19:13:35] "[35m[1mGET /sample_template/added HTTP/1.1[0m" 500 -
ERROR:werkzeug:Error on request:
Traceback (most recent call last):
  File "C:\Users\maxim\AppData\Local\Packages\PythonSoftwareFoundation.Python.3.11_qbz5n2kfra8p0\LocalCache\local-packages\Python311\site-packages\werkzeug\debug\__init__.py", line 330, in debug_application
    app_iter = self.app(environ, start_response)
               ^^^^^^^^^^^^^^^^^^^^^^^^^^^^^^^^^
  File "C:\Users\maxim\AppData\Local\Packages\PythonSoftwareFoundation.Python.3.11_qbz5n2kfra8p0\LocalCache\local-packages\Python311\site-packages\flask\app.py", line 1478, in __call__
    return self.wsgi_app(environ, start_response)
           ^^^^^^^^^^^^^^^^^^^^^^^^^^^^^^^^^^^^^^
  File "C:\Users\maxim\AppData\Local\Packages\PythonSoftwareFoundation.Python.3.11_qbz5n2kfra8p0\LocalCache\local-packages\Python311\site-packages\flask\app.py", line 1458, in wsgi_app
    response = self.handle_exception(e)
               ^^^^^^^^^^^^^^^^^^^^^^^^
  File "C:\Users\maxim\AppData\Local\Packages\PythonSoftwareFoundation.Python.3.11_qbz5n2kfra8p0\LocalCache\local-packages\Python311\site-packages\flask\app.py", line 1455, in wsgi_app
    response = self.full_dispatch_request()
               ^^^^^^^^^^^^^^^^^^^^^^^^^^^^
  File "C:\Users\maxim\AppData\Local\Packages\PythonSoftwareFoundation.Python.3.11_qbz5n2kfra8p0\LocalCache\local-packages\Python311\site-packages\flask\app.py", line 869, in full_dispatch_request
    rv = self.handle_user_exception(e)
         ^^^^^^^^^^^^^^^^^^^^^^^^^^^^^
  File "C:\Users\maxim\AppData\Local\Packages\PythonSoftwareFoundation.Python.3.11_qbz5n2kfra8p0\LocalCache\local-packages\Python311\site-packages\flask\app.py", line 867, in full_dispatch_request
    rv = self.dispatch_request()
         ^^^^^^^^^^^^^^^^^^^^^^^
  File "C:\Users\maxim\AppData\Local\Packages\PythonSoftwareFoundation.Python.3.11_qbz5n2kfra8p0\LocalCache\local-packages\Python311\site-packages\flask\app.py", line 852, in dispatch_request
    return self.ensure_sync(self.view_functions[rule.endpoint])(**view_args)
           ^^^^^^^^^^^^^^^^^^^^^^^^^^^^^^^^^^^^^^^^^^^^^^^^^^^^^^^^^^^^^^^^^
  File "c:\xampp\htdocs\ProjectAutomation\app.py", line 216, in added
    print(rows)
OSError: [Errno 22] Invalid argument

During handling of the above exception, another exception occurred:

Traceback (most recent call last):
  File "C:\Users\maxim\AppData\Local\Packages\PythonSoftwareFoundation.Python.3.11_qbz5n2kfra8p0\LocalCache\local-packages\Python311\site-packages\werkzeug\serving.py", line 362, in run_wsgi
    execute(self.server.app)
  File "C:\Users\maxim\AppData\Local\Packages\PythonSoftwareFoundation.Python.3.11_qbz5n2kfra8p0\LocalCache\local-packages\Python311\site-packages\werkzeug\serving.py", line 325, in execute
    for data in application_iter:
  File "C:\Users\maxim\AppData\Local\Packages\PythonSoftwareFoundation.Python.3.11_qbz5n2kfra8p0\LocalCache\local-packages\Python311\site-packages\werkzeug\debug\__init__.py", line 365, in debug_application
    environ["wsgi.errors"].write("".join(tb.render_traceback_text()))
OSError: [Errno 22] Invalid argument
INFO:werkzeug:127.0.0.1 - - [15/Nov/2023 19:13:35] "[36mGET /sample_template/added?__debugger__=yes&cmd=resource&f=style.css HTTP/1.1[0m" 304 -
INFO:werkzeug:127.0.0.1 - - [15/Nov/2023 19:13:35] "[36mGET /sample_template/added?__debugger__=yes&cmd=resource&f=debugger.js HTTP/1.1[0m" 304 -
INFO:werkzeug:127.0.0.1 - - [15/Nov/2023 19:13:35] "[36mGET /sample_template/added?__debugger__=yes&cmd=resource&f=console.png HTTP/1.1[0m" 304 -
INFO:werkzeug: * Detected change in 'c:\\xampp\\htdocs\\ProjectAutomation\\app.py', reloading
INFO:werkzeug: * Restarting with stat
INFO:werkzeug: * Detected change in 'c:\\xampp\\htdocs\\ProjectAutomation\\app.py', reloading
INFO:werkzeug: * Detected change in 'c:\\xampp\\htdocs\\ProjectAutomation\\app.py', reloading
INFO:werkzeug: * Restarting with stat
INFO:werkzeug: * Restarting with stat
DEBUG:mysql.connector:# _do_auth(): self._auth_plugin: 
DEBUG:mysql.connector:new_auth_plugin: caching_sha2_password
WARNING:werkzeug: * Debugger is active!
INFO:werkzeug: * Debugger PIN: 128-007-232
DEBUG:mysql.connector:# _do_auth(): self._auth_plugin: 
DEBUG:mysql.connector:new_auth_plugin: caching_sha2_password
WARNING:werkzeug: * Debugger is active!
INFO:werkzeug: * Debugger PIN: 128-007-232
DEBUG:mysql.connector:# _do_auth(): self._auth_plugin: 
DEBUG:mysql.connector:new_auth_plugin: caching_sha2_password
WARNING:werkzeug: * Debugger is active!
INFO:werkzeug: * Debugger PIN: 128-007-232
DEBUG:mysql.connector:# _do_auth(): self._auth_plugin: 
DEBUG:mysql.connector:new_auth_plugin: caching_sha2_password
INFO:werkzeug:127.0.0.1 - - [15/Nov/2023 19:13:50] "[35m[1mGET /sample_template/added HTTP/1.1[0m" 500 -
ERROR:werkzeug:Error on request:
Traceback (most recent call last):
  File "C:\Users\maxim\AppData\Local\Packages\PythonSoftwareFoundation.Python.3.11_qbz5n2kfra8p0\LocalCache\local-packages\Python311\site-packages\werkzeug\debug\__init__.py", line 330, in debug_application
    app_iter = self.app(environ, start_response)
               ^^^^^^^^^^^^^^^^^^^^^^^^^^^^^^^^^
  File "C:\Users\maxim\AppData\Local\Packages\PythonSoftwareFoundation.Python.3.11_qbz5n2kfra8p0\LocalCache\local-packages\Python311\site-packages\flask\app.py", line 1478, in __call__
    return self.wsgi_app(environ, start_response)
           ^^^^^^^^^^^^^^^^^^^^^^^^^^^^^^^^^^^^^^
  File "C:\Users\maxim\AppData\Local\Packages\PythonSoftwareFoundation.Python.3.11_qbz5n2kfra8p0\LocalCache\local-packages\Python311\site-packages\flask\app.py", line 1458, in wsgi_app
    response = self.handle_exception(e)
               ^^^^^^^^^^^^^^^^^^^^^^^^
  File "C:\Users\maxim\AppData\Local\Packages\PythonSoftwareFoundation.Python.3.11_qbz5n2kfra8p0\LocalCache\local-packages\Python311\site-packages\flask\app.py", line 1455, in wsgi_app
    response = self.full_dispatch_request()
               ^^^^^^^^^^^^^^^^^^^^^^^^^^^^
  File "C:\Users\maxim\AppData\Local\Packages\PythonSoftwareFoundation.Python.3.11_qbz5n2kfra8p0\LocalCache\local-packages\Python311\site-packages\flask\app.py", line 869, in full_dispatch_request
    rv = self.handle_user_exception(e)
         ^^^^^^^^^^^^^^^^^^^^^^^^^^^^^
  File "C:\Users\maxim\AppData\Local\Packages\PythonSoftwareFoundation.Python.3.11_qbz5n2kfra8p0\LocalCache\local-packages\Python311\site-packages\flask\app.py", line 867, in full_dispatch_request
    rv = self.dispatch_request()
         ^^^^^^^^^^^^^^^^^^^^^^^
  File "C:\Users\maxim\AppData\Local\Packages\PythonSoftwareFoundation.Python.3.11_qbz5n2kfra8p0\LocalCache\local-packages\Python311\site-packages\flask\app.py", line 852, in dispatch_request
    return self.ensure_sync(self.view_functions[rule.endpoint])(**view_args)
           ^^^^^^^^^^^^^^^^^^^^^^^^^^^^^^^^^^^^^^^^^^^^^^^^^^^^^^^^^^^^^^^^^
  File "c:\xampp\htdocs\ProjectAutomation\app.py", line 227, in added
    print(event)
OSError: [Errno 22] Invalid argument

During handling of the above exception, another exception occurred:

Traceback (most recent call last):
  File "C:\Users\maxim\AppData\Local\Packages\PythonSoftwareFoundation.Python.3.11_qbz5n2kfra8p0\LocalCache\local-packages\Python311\site-packages\werkzeug\serving.py", line 362, in run_wsgi
    execute(self.server.app)
  File "C:\Users\maxim\AppData\Local\Packages\PythonSoftwareFoundation.Python.3.11_qbz5n2kfra8p0\LocalCache\local-packages\Python311\site-packages\werkzeug\serving.py", line 325, in execute
    for data in application_iter:
  File "C:\Users\maxim\AppData\Local\Packages\PythonSoftwareFoundation.Python.3.11_qbz5n2kfra8p0\LocalCache\local-packages\Python311\site-packages\werkzeug\debug\__init__.py", line 365, in debug_application
    environ["wsgi.errors"].write("".join(tb.render_traceback_text()))
OSError: [Errno 22] Invalid argument
INFO:werkzeug:127.0.0.1 - - [15/Nov/2023 19:13:50] "[36mGET /sample_template/added?__debugger__=yes&cmd=resource&f=style.css HTTP/1.1[0m" 304 -
INFO:werkzeug:127.0.0.1 - - [15/Nov/2023 19:13:50] "[36mGET /sample_template/added?__debugger__=yes&cmd=resource&f=debugger.js HTTP/1.1[0m" 304 -
INFO:werkzeug:127.0.0.1 - - [15/Nov/2023 19:13:50] "[36mGET /sample_template/added?__debugger__=yes&cmd=resource&f=console.png HTTP/1.1[0m" 304 -
INFO:werkzeug:127.0.0.1 - - [15/Nov/2023 19:13:50] "[36mGET /sample_template/added?__debugger__=yes&cmd=resource&f=console.png HTTP/1.1[0m" 304 -
INFO:werkzeug: * Detected change in 'c:\\xampp\\htdocs\\ProjectAutomation\\app.py', reloading
INFO:werkzeug: * Restarting with stat
INFO:werkzeug: * Detected change in 'c:\\xampp\\htdocs\\ProjectAutomation\\app.py', reloading
INFO:werkzeug: * Detected change in 'c:\\xampp\\htdocs\\ProjectAutomation\\app.py', reloading
INFO:werkzeug: * Restarting with stat
INFO:werkzeug: * Restarting with stat
DEBUG:mysql.connector:# _do_auth(): self._auth_plugin: 
DEBUG:mysql.connector:new_auth_plugin: caching_sha2_password
WARNING:werkzeug: * Debugger is active!
INFO:werkzeug: * Debugger PIN: 128-007-232
DEBUG:mysql.connector:# _do_auth(): self._auth_plugin: 
DEBUG:mysql.connector:new_auth_plugin: caching_sha2_password
WARNING:werkzeug: * Debugger is active!
INFO:werkzeug: * Debugger PIN: 128-007-232
DEBUG:mysql.connector:# _do_auth(): self._auth_plugin: 
DEBUG:mysql.connector:new_auth_plugin: caching_sha2_password
WARNING:werkzeug: * Debugger is active!
INFO:werkzeug: * Debugger PIN: 128-007-232
DEBUG:mysql.connector:# _do_auth(): self._auth_plugin: 
DEBUG:mysql.connector:new_auth_plugin: caching_sha2_password
INFO:googleapiclient.discovery_cache:file_cache is only supported with oauth2client<4.0.0
DEBUG:mysql.connector:# _do_auth(): self._auth_plugin: 
DEBUG:mysql.connector:new_auth_plugin: caching_sha2_password
ERROR:root:Error: 1064 (42000): You have an error in your SQL syntax; check the manual that corresponds to your MySQL server version for the right syntax to use near '' at line 1
INFO:werkzeug:127.0.0.1 - - [15/Nov/2023 19:14:02] "[35m[1mGET /sample_template/added HTTP/1.1[0m" 500 -
ERROR:werkzeug:Error on request:
Traceback (most recent call last):
  File "C:\Users\maxim\AppData\Local\Packages\PythonSoftwareFoundation.Python.3.11_qbz5n2kfra8p0\LocalCache\local-packages\Python311\site-packages\werkzeug\debug\__init__.py", line 330, in debug_application
    app_iter = self.app(environ, start_response)
               ^^^^^^^^^^^^^^^^^^^^^^^^^^^^^^^^^
  File "C:\Users\maxim\AppData\Local\Packages\PythonSoftwareFoundation.Python.3.11_qbz5n2kfra8p0\LocalCache\local-packages\Python311\site-packages\flask\app.py", line 1478, in __call__
    return self.wsgi_app(environ, start_response)
           ^^^^^^^^^^^^^^^^^^^^^^^^^^^^^^^^^^^^^^
  File "C:\Users\maxim\AppData\Local\Packages\PythonSoftwareFoundation.Python.3.11_qbz5n2kfra8p0\LocalCache\local-packages\Python311\site-packages\flask\app.py", line 1458, in wsgi_app
    response = self.handle_exception(e)
               ^^^^^^^^^^^^^^^^^^^^^^^^
  File "C:\Users\maxim\AppData\Local\Packages\PythonSoftwareFoundation.Python.3.11_qbz5n2kfra8p0\LocalCache\local-packages\Python311\site-packages\flask\app.py", line 1455, in wsgi_app
    response = self.full_dispatch_request()
               ^^^^^^^^^^^^^^^^^^^^^^^^^^^^
  File "C:\Users\maxim\AppData\Local\Packages\PythonSoftwareFoundation.Python.3.11_qbz5n2kfra8p0\LocalCache\local-packages\Python311\site-packages\flask\app.py", line 869, in full_dispatch_request
    rv = self.handle_user_exception(e)
         ^^^^^^^^^^^^^^^^^^^^^^^^^^^^^
  File "C:\Users\maxim\AppData\Local\Packages\PythonSoftwareFoundation.Python.3.11_qbz5n2kfra8p0\LocalCache\local-packages\Python311\site-packages\flask\app.py", line 867, in full_dispatch_request
    rv = self.dispatch_request()
         ^^^^^^^^^^^^^^^^^^^^^^^
  File "C:\Users\maxim\AppData\Local\Packages\PythonSoftwareFoundation.Python.3.11_qbz5n2kfra8p0\LocalCache\local-packages\Python311\site-packages\flask\app.py", line 852, in dispatch_request
    return self.ensure_sync(self.view_functions[rule.endpoint])(**view_args)
           ^^^^^^^^^^^^^^^^^^^^^^^^^^^^^^^^^^^^^^^^^^^^^^^^^^^^^^^^^^^^^^^^^
  File "c:\xampp\htdocs\ProjectAutomation\app.py", line 230, in added
    main.add(events)
  File "c:\xampp\htdocs\ProjectAutomation\main.py", line 45, in add
    print(event)
OSError: [Errno 22] Invalid argument

During handling of the above exception, another exception occurred:

Traceback (most recent call last):
  File "C:\Users\maxim\AppData\Local\Packages\PythonSoftwareFoundation.Python.3.11_qbz5n2kfra8p0\LocalCache\local-packages\Python311\site-packages\werkzeug\serving.py", line 362, in run_wsgi
    execute(self.server.app)
  File "C:\Users\maxim\AppData\Local\Packages\PythonSoftwareFoundation.Python.3.11_qbz5n2kfra8p0\LocalCache\local-packages\Python311\site-packages\werkzeug\serving.py", line 325, in execute
    for data in application_iter:
  File "C:\Users\maxim\AppData\Local\Packages\PythonSoftwareFoundation.Python.3.11_qbz5n2kfra8p0\LocalCache\local-packages\Python311\site-packages\werkzeug\debug\__init__.py", line 365, in debug_application
    environ["wsgi.errors"].write("".join(tb.render_traceback_text()))
OSError: [Errno 22] Invalid argument
INFO:werkzeug:127.0.0.1 - - [15/Nov/2023 19:14:02] "[36mGET /sample_template/added?__debugger__=yes&cmd=resource&f=style.css HTTP/1.1[0m" 304 -
INFO:werkzeug:127.0.0.1 - - [15/Nov/2023 19:14:03] "[36mGET /sample_template/added?__debugger__=yes&cmd=resource&f=debugger.js HTTP/1.1[0m" 304 -
INFO:werkzeug:127.0.0.1 - - [15/Nov/2023 19:14:03] "[36mGET /sample_template/added?__debugger__=yes&cmd=resource&f=console.png HTTP/1.1[0m" 304 -
INFO:werkzeug:127.0.0.1 - - [15/Nov/2023 19:14:03] "[36mGET /sample_template/added?__debugger__=yes&cmd=resource&f=console.png HTTP/1.1[0m" 304 -
DEBUG:mysql.connector:# _do_auth(): self._auth_plugin: 
DEBUG:mysql.connector:new_auth_plugin: caching_sha2_password
INFO:googleapiclient.discovery_cache:file_cache is only supported with oauth2client<4.0.0
DEBUG:mysql.connector:# _do_auth(): self._auth_plugin: 
DEBUG:mysql.connector:new_auth_plugin: caching_sha2_password
ERROR:root:Error: 1064 (42000): You have an error in your SQL syntax; check the manual that corresponds to your MySQL server version for the right syntax to use near '' at line 1
INFO:werkzeug:127.0.0.1 - - [15/Nov/2023 19:14:03] "[35m[1mGET /sample_template/added HTTP/1.1[0m" 500 -
ERROR:werkzeug:Error on request:
Traceback (most recent call last):
  File "C:\Users\maxim\AppData\Local\Packages\PythonSoftwareFoundation.Python.3.11_qbz5n2kfra8p0\LocalCache\local-packages\Python311\site-packages\werkzeug\debug\__init__.py", line 330, in debug_application
    app_iter = self.app(environ, start_response)
               ^^^^^^^^^^^^^^^^^^^^^^^^^^^^^^^^^
  File "C:\Users\maxim\AppData\Local\Packages\PythonSoftwareFoundation.Python.3.11_qbz5n2kfra8p0\LocalCache\local-packages\Python311\site-packages\flask\app.py", line 1478, in __call__
    return self.wsgi_app(environ, start_response)
           ^^^^^^^^^^^^^^^^^^^^^^^^^^^^^^^^^^^^^^
  File "C:\Users\maxim\AppData\Local\Packages\PythonSoftwareFoundation.Python.3.11_qbz5n2kfra8p0\LocalCache\local-packages\Python311\site-packages\flask\app.py", line 1458, in wsgi_app
    response = self.handle_exception(e)
               ^^^^^^^^^^^^^^^^^^^^^^^^
  File "C:\Users\maxim\AppData\Local\Packages\PythonSoftwareFoundation.Python.3.11_qbz5n2kfra8p0\LocalCache\local-packages\Python311\site-packages\flask\app.py", line 1455, in wsgi_app
    response = self.full_dispatch_request()
               ^^^^^^^^^^^^^^^^^^^^^^^^^^^^
  File "C:\Users\maxim\AppData\Local\Packages\PythonSoftwareFoundation.Python.3.11_qbz5n2kfra8p0\LocalCache\local-packages\Python311\site-packages\flask\app.py", line 869, in full_dispatch_request
    rv = self.handle_user_exception(e)
         ^^^^^^^^^^^^^^^^^^^^^^^^^^^^^
  File "C:\Users\maxim\AppData\Local\Packages\PythonSoftwareFoundation.Python.3.11_qbz5n2kfra8p0\LocalCache\local-packages\Python311\site-packages\flask\app.py", line 867, in full_dispatch_request
    rv = self.dispatch_request()
         ^^^^^^^^^^^^^^^^^^^^^^^
  File "C:\Users\maxim\AppData\Local\Packages\PythonSoftwareFoundation.Python.3.11_qbz5n2kfra8p0\LocalCache\local-packages\Python311\site-packages\flask\app.py", line 852, in dispatch_request
    return self.ensure_sync(self.view_functions[rule.endpoint])(**view_args)
           ^^^^^^^^^^^^^^^^^^^^^^^^^^^^^^^^^^^^^^^^^^^^^^^^^^^^^^^^^^^^^^^^^
  File "c:\xampp\htdocs\ProjectAutomation\app.py", line 230, in added
    main.add(events)
  File "c:\xampp\htdocs\ProjectAutomation\main.py", line 45, in add
    print(event)
OSError: [Errno 22] Invalid argument

During handling of the above exception, another exception occurred:

Traceback (most recent call last):
  File "C:\Users\maxim\AppData\Local\Packages\PythonSoftwareFoundation.Python.3.11_qbz5n2kfra8p0\LocalCache\local-packages\Python311\site-packages\werkzeug\serving.py", line 362, in run_wsgi
    execute(self.server.app)
  File "C:\Users\maxim\AppData\Local\Packages\PythonSoftwareFoundation.Python.3.11_qbz5n2kfra8p0\LocalCache\local-packages\Python311\site-packages\werkzeug\serving.py", line 325, in execute
    for data in application_iter:
  File "C:\Users\maxim\AppData\Local\Packages\PythonSoftwareFoundation.Python.3.11_qbz5n2kfra8p0\LocalCache\local-packages\Python311\site-packages\werkzeug\debug\__init__.py", line 365, in debug_application
    environ["wsgi.errors"].write("".join(tb.render_traceback_text()))
OSError: [Errno 22] Invalid argument
INFO:werkzeug:127.0.0.1 - - [15/Nov/2023 19:14:03] "[36mGET /sample_template/added?__debugger__=yes&cmd=resource&f=style.css HTTP/1.1[0m" 304 -
INFO:werkzeug:127.0.0.1 - - [15/Nov/2023 19:14:03] "[36mGET /sample_template/added?__debugger__=yes&cmd=resource&f=debugger.js HTTP/1.1[0m" 304 -
INFO:werkzeug:127.0.0.1 - - [15/Nov/2023 19:14:03] "[36mGET /sample_template/added?__debugger__=yes&cmd=resource&f=console.png HTTP/1.1[0m" 304 -
INFO:werkzeug:127.0.0.1 - - [15/Nov/2023 19:14:03] "[36mGET /sample_template/added?__debugger__=yes&cmd=resource&f=console.png HTTP/1.1[0m" 304 -
INFO:werkzeug: * Detected change in 'c:\\xampp\\htdocs\\ProjectAutomation\\app.py', reloading
INFO:werkzeug: * Restarting with stat
INFO:werkzeug: * Detected change in 'c:\\xampp\\htdocs\\ProjectAutomation\\app.py', reloading
INFO:werkzeug: * Restarting with stat
INFO:werkzeug: * Detected change in 'c:\\xampp\\htdocs\\ProjectAutomation\\app.py', reloading
INFO:werkzeug: * Restarting with stat
DEBUG:mysql.connector:# _do_auth(): self._auth_plugin: 
DEBUG:mysql.connector:new_auth_plugin: caching_sha2_password
WARNING:werkzeug: * Debugger is active!
INFO:werkzeug: * Debugger PIN: 128-007-232
DEBUG:mysql.connector:# _do_auth(): self._auth_plugin: 
DEBUG:mysql.connector:new_auth_plugin: caching_sha2_password
WARNING:werkzeug: * Debugger is active!
INFO:werkzeug: * Debugger PIN: 128-007-232
DEBUG:mysql.connector:# _do_auth(): self._auth_plugin: 
DEBUG:mysql.connector:new_auth_plugin: caching_sha2_password
WARNING:werkzeug: * Debugger is active!
INFO:werkzeug: * Debugger PIN: 128-007-232
DEBUG:mysql.connector:# _do_auth(): self._auth_plugin: 
DEBUG:mysql.connector:new_auth_plugin: caching_sha2_password
INFO:googleapiclient.discovery_cache:file_cache is only supported with oauth2client<4.0.0
DEBUG:mysql.connector:# _do_auth(): self._auth_plugin: 
DEBUG:mysql.connector:new_auth_plugin: caching_sha2_password
ERROR:root:Error: 1064 (42000): You have an error in your SQL syntax; check the manual that corresponds to your MySQL server version for the right syntax to use near '' at line 1
INFO:werkzeug:127.0.0.1 - - [15/Nov/2023 19:14:09] "[35m[1mGET /sample_template/added HTTP/1.1[0m" 500 -
ERROR:werkzeug:Error on request:
Traceback (most recent call last):
  File "C:\Users\maxim\AppData\Local\Packages\PythonSoftwareFoundation.Python.3.11_qbz5n2kfra8p0\LocalCache\local-packages\Python311\site-packages\werkzeug\debug\__init__.py", line 330, in debug_application
    app_iter = self.app(environ, start_response)
               ^^^^^^^^^^^^^^^^^^^^^^^^^^^^^^^^^
  File "C:\Users\maxim\AppData\Local\Packages\PythonSoftwareFoundation.Python.3.11_qbz5n2kfra8p0\LocalCache\local-packages\Python311\site-packages\flask\app.py", line 1478, in __call__
    return self.wsgi_app(environ, start_response)
           ^^^^^^^^^^^^^^^^^^^^^^^^^^^^^^^^^^^^^^
  File "C:\Users\maxim\AppData\Local\Packages\PythonSoftwareFoundation.Python.3.11_qbz5n2kfra8p0\LocalCache\local-packages\Python311\site-packages\flask\app.py", line 1458, in wsgi_app
    response = self.handle_exception(e)
               ^^^^^^^^^^^^^^^^^^^^^^^^
  File "C:\Users\maxim\AppData\Local\Packages\PythonSoftwareFoundation.Python.3.11_qbz5n2kfra8p0\LocalCache\local-packages\Python311\site-packages\flask\app.py", line 1455, in wsgi_app
    response = self.full_dispatch_request()
               ^^^^^^^^^^^^^^^^^^^^^^^^^^^^
  File "C:\Users\maxim\AppData\Local\Packages\PythonSoftwareFoundation.Python.3.11_qbz5n2kfra8p0\LocalCache\local-packages\Python311\site-packages\flask\app.py", line 869, in full_dispatch_request
    rv = self.handle_user_exception(e)
         ^^^^^^^^^^^^^^^^^^^^^^^^^^^^^
  File "C:\Users\maxim\AppData\Local\Packages\PythonSoftwareFoundation.Python.3.11_qbz5n2kfra8p0\LocalCache\local-packages\Python311\site-packages\flask\app.py", line 867, in full_dispatch_request
    rv = self.dispatch_request()
         ^^^^^^^^^^^^^^^^^^^^^^^
  File "C:\Users\maxim\AppData\Local\Packages\PythonSoftwareFoundation.Python.3.11_qbz5n2kfra8p0\LocalCache\local-packages\Python311\site-packages\flask\app.py", line 852, in dispatch_request
    return self.ensure_sync(self.view_functions[rule.endpoint])(**view_args)
           ^^^^^^^^^^^^^^^^^^^^^^^^^^^^^^^^^^^^^^^^^^^^^^^^^^^^^^^^^^^^^^^^^
  File "c:\xampp\htdocs\ProjectAutomation\app.py", line 230, in added
    main.add(events)
  File "c:\xampp\htdocs\ProjectAutomation\main.py", line 45, in add
    print(event)
OSError: [Errno 22] Invalid argument

During handling of the above exception, another exception occurred:

Traceback (most recent call last):
  File "C:\Users\maxim\AppData\Local\Packages\PythonSoftwareFoundation.Python.3.11_qbz5n2kfra8p0\LocalCache\local-packages\Python311\site-packages\werkzeug\serving.py", line 362, in run_wsgi
    execute(self.server.app)
  File "C:\Users\maxim\AppData\Local\Packages\PythonSoftwareFoundation.Python.3.11_qbz5n2kfra8p0\LocalCache\local-packages\Python311\site-packages\werkzeug\serving.py", line 325, in execute
    for data in application_iter:
  File "C:\Users\maxim\AppData\Local\Packages\PythonSoftwareFoundation.Python.3.11_qbz5n2kfra8p0\LocalCache\local-packages\Python311\site-packages\werkzeug\debug\__init__.py", line 365, in debug_application
    environ["wsgi.errors"].write("".join(tb.render_traceback_text()))
OSError: [Errno 22] Invalid argument
INFO:werkzeug:127.0.0.1 - - [15/Nov/2023 19:14:09] "[36mGET /sample_template/added?__debugger__=yes&cmd=resource&f=style.css HTTP/1.1[0m" 304 -
INFO:werkzeug:127.0.0.1 - - [15/Nov/2023 19:14:09] "[36mGET /sample_template/added?__debugger__=yes&cmd=resource&f=debugger.js HTTP/1.1[0m" 304 -
INFO:werkzeug:127.0.0.1 - - [15/Nov/2023 19:14:09] "[36mGET /sample_template/added?__debugger__=yes&cmd=resource&f=console.png HTTP/1.1[0m" 304 -
INFO:werkzeug:127.0.0.1 - - [15/Nov/2023 19:14:09] "[36mGET /sample_template/added?__debugger__=yes&cmd=resource&f=console.png HTTP/1.1[0m" 304 -
INFO:werkzeug: * Detected change in 'c:\\xampp\\htdocs\\ProjectAutomation\\main.py', reloading
INFO:werkzeug: * Restarting with stat
INFO:werkzeug: * Detected change in 'c:\\xampp\\htdocs\\ProjectAutomation\\main.py', reloading
INFO:werkzeug: * Detected change in 'c:\\xampp\\htdocs\\ProjectAutomation\\main.py', reloading
INFO:werkzeug: * Restarting with stat
INFO:werkzeug: * Restarting with stat
DEBUG:mysql.connector:# _do_auth(): self._auth_plugin: 
DEBUG:mysql.connector:new_auth_plugin: caching_sha2_password
WARNING:werkzeug: * Debugger is active!
INFO:werkzeug: * Debugger PIN: 128-007-232
DEBUG:mysql.connector:# _do_auth(): self._auth_plugin: 
DEBUG:mysql.connector:new_auth_plugin: caching_sha2_password
DEBUG:mysql.connector:# _do_auth(): self._auth_plugin: 
DEBUG:mysql.connector:new_auth_plugin: caching_sha2_password
WARNING:werkzeug: * Debugger is active!
INFO:werkzeug: * Debugger PIN: 128-007-232
WARNING:werkzeug: * Debugger is active!
INFO:werkzeug: * Debugger PIN: 128-007-232
DEBUG:mysql.connector:# _do_auth(): self._auth_plugin: 
DEBUG:mysql.connector:new_auth_plugin: caching_sha2_password
INFO:googleapiclient.discovery_cache:file_cache is only supported with oauth2client<4.0.0
DEBUG:mysql.connector:# _do_auth(): self._auth_plugin: 
DEBUG:mysql.connector:new_auth_plugin: caching_sha2_password
ERROR:root:Error: 1064 (42000): You have an error in your SQL syntax; check the manual that corresponds to your MySQL server version for the right syntax to use near '' at line 1
INFO:werkzeug:127.0.0.1 - - [15/Nov/2023 19:14:26] "[35m[1mGET /sample_template/added HTTP/1.1[0m" 500 -
ERROR:werkzeug:Error on request:
Traceback (most recent call last):
  File "C:\Users\maxim\AppData\Local\Packages\PythonSoftwareFoundation.Python.3.11_qbz5n2kfra8p0\LocalCache\local-packages\Python311\site-packages\werkzeug\debug\__init__.py", line 330, in debug_application
    app_iter = self.app(environ, start_response)
               ^^^^^^^^^^^^^^^^^^^^^^^^^^^^^^^^^
  File "C:\Users\maxim\AppData\Local\Packages\PythonSoftwareFoundation.Python.3.11_qbz5n2kfra8p0\LocalCache\local-packages\Python311\site-packages\flask\app.py", line 1478, in __call__
    return self.wsgi_app(environ, start_response)
           ^^^^^^^^^^^^^^^^^^^^^^^^^^^^^^^^^^^^^^
  File "C:\Users\maxim\AppData\Local\Packages\PythonSoftwareFoundation.Python.3.11_qbz5n2kfra8p0\LocalCache\local-packages\Python311\site-packages\flask\app.py", line 1458, in wsgi_app
    response = self.handle_exception(e)
               ^^^^^^^^^^^^^^^^^^^^^^^^
  File "C:\Users\maxim\AppData\Local\Packages\PythonSoftwareFoundation.Python.3.11_qbz5n2kfra8p0\LocalCache\local-packages\Python311\site-packages\flask\app.py", line 1455, in wsgi_app
    response = self.full_dispatch_request()
               ^^^^^^^^^^^^^^^^^^^^^^^^^^^^
  File "C:\Users\maxim\AppData\Local\Packages\PythonSoftwareFoundation.Python.3.11_qbz5n2kfra8p0\LocalCache\local-packages\Python311\site-packages\flask\app.py", line 869, in full_dispatch_request
    rv = self.handle_user_exception(e)
         ^^^^^^^^^^^^^^^^^^^^^^^^^^^^^
  File "C:\Users\maxim\AppData\Local\Packages\PythonSoftwareFoundation.Python.3.11_qbz5n2kfra8p0\LocalCache\local-packages\Python311\site-packages\flask\app.py", line 867, in full_dispatch_request
    rv = self.dispatch_request()
         ^^^^^^^^^^^^^^^^^^^^^^^
  File "C:\Users\maxim\AppData\Local\Packages\PythonSoftwareFoundation.Python.3.11_qbz5n2kfra8p0\LocalCache\local-packages\Python311\site-packages\flask\app.py", line 852, in dispatch_request
    return self.ensure_sync(self.view_functions[rule.endpoint])(**view_args)
           ^^^^^^^^^^^^^^^^^^^^^^^^^^^^^^^^^^^^^^^^^^^^^^^^^^^^^^^^^^^^^^^^^
  File "c:\xampp\htdocs\ProjectAutomation\app.py", line 230, in added
    main.add(events)
  File "c:\xampp\htdocs\ProjectAutomation\main.py", line 48, in add
    event = service.events().insert(calendarId="primary", body=event).execute()
            ^^^^^^^^^^^^^^^^^^^^^^^^^^^^^^^^^^^^^^^^^^^^^^^^^^^^^^^^^^^^^^^^^^^
  File "C:\Users\maxim\AppData\Local\Packages\PythonSoftwareFoundation.Python.3.11_qbz5n2kfra8p0\LocalCache\local-packages\Python311\site-packages\googleapiclient\discovery.py", line 1123, in method
    headers, params, query, body = model.request(
                                   ^^^^^^^^^^^^^^
  File "C:\Users\maxim\AppData\Local\Packages\PythonSoftwareFoundation.Python.3.11_qbz5n2kfra8p0\LocalCache\local-packages\Python311\site-packages\googleapiclient\model.py", line 160, in request
    body_value = self.serialize(body_value)
                 ^^^^^^^^^^^^^^^^^^^^^^^^^^
  File "C:\Users\maxim\AppData\Local\Packages\PythonSoftwareFoundation.Python.3.11_qbz5n2kfra8p0\LocalCache\local-packages\Python311\site-packages\googleapiclient\model.py", line 273, in serialize
    return json.dumps(body_value)
           ^^^^^^^^^^^^^^^^^^^^^^
  File "C:\Program Files\WindowsApps\PythonSoftwareFoundation.Python.3.11_3.11.1776.0_x64__qbz5n2kfra8p0\Lib\json\__init__.py", line 231, in dumps
    return _default_encoder.encode(obj)
           ^^^^^^^^^^^^^^^^^^^^^^^^^^^^
  File "C:\Program Files\WindowsApps\PythonSoftwareFoundation.Python.3.11_3.11.1776.0_x64__qbz5n2kfra8p0\Lib\json\encoder.py", line 200, in encode
    chunks = self.iterencode(o, _one_shot=True)
             ^^^^^^^^^^^^^^^^^^^^^^^^^^^^^^^^^^
  File "C:\Program Files\WindowsApps\PythonSoftwareFoundation.Python.3.11_3.11.1776.0_x64__qbz5n2kfra8p0\Lib\json\encoder.py", line 258, in iterencode
    return _iterencode(o, 0)
           ^^^^^^^^^^^^^^^^^
  File "C:\Program Files\WindowsApps\PythonSoftwareFoundation.Python.3.11_3.11.1776.0_x64__qbz5n2kfra8p0\Lib\json\encoder.py", line 180, in default
    raise TypeError(f'Object of type {o.__class__.__name__} '
TypeError: Object of type date is not JSON serializable

During handling of the above exception, another exception occurred:

Traceback (most recent call last):
  File "C:\Users\maxim\AppData\Local\Packages\PythonSoftwareFoundation.Python.3.11_qbz5n2kfra8p0\LocalCache\local-packages\Python311\site-packages\werkzeug\serving.py", line 362, in run_wsgi
    execute(self.server.app)
  File "C:\Users\maxim\AppData\Local\Packages\PythonSoftwareFoundation.Python.3.11_qbz5n2kfra8p0\LocalCache\local-packages\Python311\site-packages\werkzeug\serving.py", line 325, in execute
    for data in application_iter:
  File "C:\Users\maxim\AppData\Local\Packages\PythonSoftwareFoundation.Python.3.11_qbz5n2kfra8p0\LocalCache\local-packages\Python311\site-packages\werkzeug\debug\__init__.py", line 365, in debug_application
    environ["wsgi.errors"].write("".join(tb.render_traceback_text()))
OSError: [Errno 22] Invalid argument
INFO:werkzeug:127.0.0.1 - - [15/Nov/2023 19:14:27] "[36mGET /sample_template/added?__debugger__=yes&cmd=resource&f=style.css HTTP/1.1[0m" 304 -
INFO:werkzeug:127.0.0.1 - - [15/Nov/2023 19:14:27] "[36mGET /sample_template/added?__debugger__=yes&cmd=resource&f=debugger.js HTTP/1.1[0m" 304 -
INFO:werkzeug:127.0.0.1 - - [15/Nov/2023 19:14:27] "[36mGET /sample_template/added?__debugger__=yes&cmd=resource&f=console.png HTTP/1.1[0m" 304 -
INFO:werkzeug:127.0.0.1 - - [15/Nov/2023 19:14:27] "[36mGET /sample_template/added?__debugger__=yes&cmd=resource&f=console.png HTTP/1.1[0m" 304 -
DEBUG:mysql.connector:# _do_auth(): self._auth_plugin: 
DEBUG:mysql.connector:new_auth_plugin: caching_sha2_password
INFO:googleapiclient.discovery_cache:file_cache is only supported with oauth2client<4.0.0
DEBUG:mysql.connector:# _do_auth(): self._auth_plugin: 
DEBUG:mysql.connector:new_auth_plugin: caching_sha2_password
ERROR:root:Error: 1064 (42000): You have an error in your SQL syntax; check the manual that corresponds to your MySQL server version for the right syntax to use near '' at line 1
INFO:werkzeug:127.0.0.1 - - [15/Nov/2023 19:15:04] "[35m[1mGET /sample_template/added HTTP/1.1[0m" 500 -
ERROR:werkzeug:Error on request:
Traceback (most recent call last):
  File "C:\Users\maxim\AppData\Local\Packages\PythonSoftwareFoundation.Python.3.11_qbz5n2kfra8p0\LocalCache\local-packages\Python311\site-packages\werkzeug\debug\__init__.py", line 330, in debug_application
    app_iter = self.app(environ, start_response)
               ^^^^^^^^^^^^^^^^^^^^^^^^^^^^^^^^^
  File "C:\Users\maxim\AppData\Local\Packages\PythonSoftwareFoundation.Python.3.11_qbz5n2kfra8p0\LocalCache\local-packages\Python311\site-packages\flask\app.py", line 1478, in __call__
    return self.wsgi_app(environ, start_response)
           ^^^^^^^^^^^^^^^^^^^^^^^^^^^^^^^^^^^^^^
  File "C:\Users\maxim\AppData\Local\Packages\PythonSoftwareFoundation.Python.3.11_qbz5n2kfra8p0\LocalCache\local-packages\Python311\site-packages\flask\app.py", line 1458, in wsgi_app
    response = self.handle_exception(e)
               ^^^^^^^^^^^^^^^^^^^^^^^^
  File "C:\Users\maxim\AppData\Local\Packages\PythonSoftwareFoundation.Python.3.11_qbz5n2kfra8p0\LocalCache\local-packages\Python311\site-packages\flask\app.py", line 1455, in wsgi_app
    response = self.full_dispatch_request()
               ^^^^^^^^^^^^^^^^^^^^^^^^^^^^
  File "C:\Users\maxim\AppData\Local\Packages\PythonSoftwareFoundation.Python.3.11_qbz5n2kfra8p0\LocalCache\local-packages\Python311\site-packages\flask\app.py", line 869, in full_dispatch_request
    rv = self.handle_user_exception(e)
         ^^^^^^^^^^^^^^^^^^^^^^^^^^^^^
  File "C:\Users\maxim\AppData\Local\Packages\PythonSoftwareFoundation.Python.3.11_qbz5n2kfra8p0\LocalCache\local-packages\Python311\site-packages\flask\app.py", line 867, in full_dispatch_request
    rv = self.dispatch_request()
         ^^^^^^^^^^^^^^^^^^^^^^^
  File "C:\Users\maxim\AppData\Local\Packages\PythonSoftwareFoundation.Python.3.11_qbz5n2kfra8p0\LocalCache\local-packages\Python311\site-packages\flask\app.py", line 852, in dispatch_request
    return self.ensure_sync(self.view_functions[rule.endpoint])(**view_args)
           ^^^^^^^^^^^^^^^^^^^^^^^^^^^^^^^^^^^^^^^^^^^^^^^^^^^^^^^^^^^^^^^^^
  File "c:\xampp\htdocs\ProjectAutomation\app.py", line 230, in added
    main.add(events)
  File "c:\xampp\htdocs\ProjectAutomation\main.py", line 48, in add
    event = service.events().insert(calendarId="primary", body=event).execute()
            ^^^^^^^^^^^^^^^^^^^^^^^^^^^^^^^^^^^^^^^^^^^^^^^^^^^^^^^^^^^^^^^^^^^
  File "C:\Users\maxim\AppData\Local\Packages\PythonSoftwareFoundation.Python.3.11_qbz5n2kfra8p0\LocalCache\local-packages\Python311\site-packages\googleapiclient\discovery.py", line 1123, in method
    headers, params, query, body = model.request(
                                   ^^^^^^^^^^^^^^
  File "C:\Users\maxim\AppData\Local\Packages\PythonSoftwareFoundation.Python.3.11_qbz5n2kfra8p0\LocalCache\local-packages\Python311\site-packages\googleapiclient\model.py", line 160, in request
    body_value = self.serialize(body_value)
                 ^^^^^^^^^^^^^^^^^^^^^^^^^^
  File "C:\Users\maxim\AppData\Local\Packages\PythonSoftwareFoundation.Python.3.11_qbz5n2kfra8p0\LocalCache\local-packages\Python311\site-packages\googleapiclient\model.py", line 273, in serialize
    return json.dumps(body_value)
           ^^^^^^^^^^^^^^^^^^^^^^
  File "C:\Program Files\WindowsApps\PythonSoftwareFoundation.Python.3.11_3.11.1776.0_x64__qbz5n2kfra8p0\Lib\json\__init__.py", line 231, in dumps
    return _default_encoder.encode(obj)
           ^^^^^^^^^^^^^^^^^^^^^^^^^^^^
  File "C:\Program Files\WindowsApps\PythonSoftwareFoundation.Python.3.11_3.11.1776.0_x64__qbz5n2kfra8p0\Lib\json\encoder.py", line 200, in encode
    chunks = self.iterencode(o, _one_shot=True)
             ^^^^^^^^^^^^^^^^^^^^^^^^^^^^^^^^^^
  File "C:\Program Files\WindowsApps\PythonSoftwareFoundation.Python.3.11_3.11.1776.0_x64__qbz5n2kfra8p0\Lib\json\encoder.py", line 258, in iterencode
    return _iterencode(o, 0)
           ^^^^^^^^^^^^^^^^^
  File "C:\Program Files\WindowsApps\PythonSoftwareFoundation.Python.3.11_3.11.1776.0_x64__qbz5n2kfra8p0\Lib\json\encoder.py", line 180, in default
    raise TypeError(f'Object of type {o.__class__.__name__} '
TypeError: Object of type date is not JSON serializable

During handling of the above exception, another exception occurred:

Traceback (most recent call last):
  File "C:\Users\maxim\AppData\Local\Packages\PythonSoftwareFoundation.Python.3.11_qbz5n2kfra8p0\LocalCache\local-packages\Python311\site-packages\werkzeug\serving.py", line 362, in run_wsgi
    execute(self.server.app)
  File "C:\Users\maxim\AppData\Local\Packages\PythonSoftwareFoundation.Python.3.11_qbz5n2kfra8p0\LocalCache\local-packages\Python311\site-packages\werkzeug\serving.py", line 325, in execute
    for data in application_iter:
  File "C:\Users\maxim\AppData\Local\Packages\PythonSoftwareFoundation.Python.3.11_qbz5n2kfra8p0\LocalCache\local-packages\Python311\site-packages\werkzeug\debug\__init__.py", line 365, in debug_application
    environ["wsgi.errors"].write("".join(tb.render_traceback_text()))
OSError: [Errno 22] Invalid argument
INFO:werkzeug:127.0.0.1 - - [15/Nov/2023 19:15:04] "[36mGET /sample_template/added?__debugger__=yes&cmd=resource&f=style.css HTTP/1.1[0m" 304 -
INFO:werkzeug:127.0.0.1 - - [15/Nov/2023 19:15:04] "[36mGET /sample_template/added?__debugger__=yes&cmd=resource&f=debugger.js HTTP/1.1[0m" 304 -
INFO:werkzeug:127.0.0.1 - - [15/Nov/2023 19:15:04] "[36mGET /sample_template/added?__debugger__=yes&cmd=resource&f=console.png HTTP/1.1[0m" 304 -
INFO:werkzeug:127.0.0.1 - - [15/Nov/2023 19:15:04] "[36mGET /sample_template/added?__debugger__=yes&cmd=resource&f=console.png HTTP/1.1[0m" 304 -
INFO:werkzeug: * Detected change in 'c:\\xampp\\htdocs\\ProjectAutomation\\app.py', reloading
INFO:werkzeug: * Detected change in 'c:\\xampp\\htdocs\\ProjectAutomation\\app.py', reloading
INFO:werkzeug: * Restarting with stat
INFO:werkzeug: * Restarting with stat
INFO:werkzeug: * Restarting with stat
